2024-04-01 21:48:33,475:ERROR:Caught an exception [ LSTM AI ]: [Errno 2] Unable to synchronously open file (unable to open file: name = 'c:\Users\lewis\OneDrive\Desktop\Python_Scripts\Market\Model\trained_model (test).h5', errno = 2, error message = 'No such file or directory', flags = 0, o_flags = 0) Error in load_model
